<mujoco>
    <include file="shared_options.xml" />
    <include file="sr_hand_e_options.xml" />
    <asset>
        <include file="shared_assets.xml" />
    </asset>
    <worldbody>
        <geom condim="3" material="mat_plane" name="floor" pos="0 0 0" size="5 5 0.001" type="plane" />
        <body name="floor" pos="0 0 0" />
        <body name="rh_mount" pos="0 -0.5 0.2" >
            <joint name="ARTx" pos="0 0 0" axis="1 0 0" type="slide" range="-0.25 0.25" damping="20" />
            <joint name="ARTy" pos="0 0 0" axis="0 1 0" type="slide" range="-0.25 0.25" damping="20" />
            <joint name="ARTz" pos="0 0 0" axis="0 0 1" type="slide" range="-0.2 0.5" damping="10" />
            <joint name="ARRx" pos="0 0 0" axis="1 0 0" range="-.75 .75" damping="20" />
            <joint name="ARRy" pos="0 0 0" axis="0 1 0" range="-3.1416 3.1416" damping="20" />
            <joint name="ARRz" pos="0 0 0" axis="0 0 1" range="-.75 .75" damping="20" />
            <!-- shadow hand-->
            <include file="sr_hand_e_plus_model.xml" />
        </body>
        <body name="support" pos="0 0 0.05">
            <geom type="box" size="0.01 0.05 0.05" pos="-0.1 0 0"/>
            <geom type="box" size="0.01 0.05 0.05" pos="0.1 0 0"/>
        </body>
        
        <body name="AB10" pos="0 0 0.2" quat="1 -1 0 0">
            <freejoint/>
            <geom type="cylinder" size=".011 .005" quat="1 0 1 0" />
            <geom type="cylinder" size=".015 .001" pos="0 .01 0" quat="1 1 0 0"/>
            <geom type="cylinder" size=".005 .01" pos="0 .011 0" quat="1 1 0 0"/>
            <composite prefix="A" type="rope" count="21 1 1" spacing="0.03" offset="0 0 2" >
                <joint kind="main" stiffness="0.05" damping="0.005" />
                <geom type="capsule" size=".01 .01" rgba="0 0 0 1" friction="1 1 1 "/>
            </composite>
        </body>    
        <light ambient="0.2 0.2 0.2" castshadow="false" diffuse="0.8 0.8 0.8" dir="0 0 -1" directional="true" name="light0" pos="0 0 4" specular="0.3 0.3 0.3" />
    </worldbody>

    <actuator>
        <position name="A_ARTx" joint="ARTx" ctrllimited="true" ctrlrange="-0.25 0.25"   kp="500" />
        <position name="A_ARTy" joint="ARTy" ctrllimited="true" ctrlrange="-0.25 0.25"   kp="500" />
        <position name="A_ARTz" joint="ARTz" ctrllimited="true" ctrlrange="-0.2 0.5"     kp="100000" />
        <position name="A_ARRx" joint="ARRx" ctrllimited="true" ctrlrange="-.75 .75"     kp="5000" />
        <position name="A_ARRy" joint="ARRy" ctrllimited="true" ctrlrange="-3.1416 3.1415"    kp="5000" />
        <position name="A_ARRz" joint="ARRz" ctrllimited="true" ctrlrange="-.75 .75"     kp="5000" />
    </actuator>
</mujoco>
